[2024-02-02T19:26:20.673+0000] {taskinstance.py:1956} INFO - Dependencies all met for dep_context=non-requeueable deps ti=<TaskInstance: etl_covid.load_to_mysql manual__2024-02-02T19:26:15.284552+00:00 [queued]>
[2024-02-02T19:26:20.683+0000] {taskinstance.py:1956} INFO - Dependencies all met for dep_context=requeueable deps ti=<TaskInstance: etl_covid.load_to_mysql manual__2024-02-02T19:26:15.284552+00:00 [queued]>
[2024-02-02T19:26:20.683+0000] {taskinstance.py:2170} INFO - Starting attempt 1 of 2
[2024-02-02T19:26:20.705+0000] {taskinstance.py:2191} INFO - Executing <Task(PythonOperator): load_to_mysql> on 2024-02-02 19:26:15.284552+00:00
[2024-02-02T19:26:20.712+0000] {standard_task_runner.py:60} INFO - Started process 360302 to run task
[2024-02-02T19:26:20.718+0000] {standard_task_runner.py:87} INFO - Running: ['airflow', 'tasks', 'run', 'etl_covid', 'load_to_mysql', 'manual__2024-02-02T19:26:15.284552+00:00', '--job-id', '19', '--raw', '--subdir', 'DAGS_FOLDER/scripts/Test.py', '--cfg-path', '/tmp/tmp0tg9np6r']
[2024-02-02T19:26:20.719+0000] {standard_task_runner.py:88} INFO - Job 19: Subtask load_to_mysql
[2024-02-02T19:26:20.787+0000] {task_command.py:423} INFO - Running <TaskInstance: etl_covid.load_to_mysql manual__2024-02-02T19:26:15.284552+00:00 [running]> on host bf5510de8451
[2024-02-02T19:26:20.911+0000] {taskinstance.py:2480} INFO - Exporting env vars: AIRFLOW_CTX_DAG_OWNER='airflow' AIRFLOW_CTX_DAG_ID='etl_covid' AIRFLOW_CTX_TASK_ID='load_to_mysql' AIRFLOW_CTX_EXECUTION_DATE='2024-02-02T19:26:15.284552+00:00' AIRFLOW_CTX_TRY_NUMBER='1' AIRFLOW_CTX_DAG_RUN_ID='manual__2024-02-02T19:26:15.284552+00:00'
[2024-02-02T19:26:20.914+0000] {taskinstance.py:2698} ERROR - Task failed with exception
Traceback (most recent call last):
  File "/home/airflow/.local/lib/python3.8/site-packages/airflow/models/taskinstance.py", line 433, in _execute_task
    result = execute_callable(context=context, **execute_callable_kwargs)
  File "/home/airflow/.local/lib/python3.8/site-packages/airflow/operators/python.py", line 199, in execute
    return_value = self.execute_callable()
  File "/home/airflow/.local/lib/python3.8/site-packages/airflow/operators/python.py", line 216, in execute_callable
    return self.python_callable(*self.op_args, **self.op_kwargs)
  File "/opt/airflow/dags/scripts/Test.py", line 73, in func_load_to_mysql
    df = extract_data()
TypeError: 'PythonOperator' object is not callable
[2024-02-02T19:26:20.926+0000] {taskinstance.py:1138} INFO - Marking task as UP_FOR_RETRY. dag_id=etl_covid, task_id=load_to_mysql, execution_date=20240202T192615, start_date=20240202T192620, end_date=20240202T192620
[2024-02-02T19:26:20.947+0000] {standard_task_runner.py:107} ERROR - Failed to execute job 19 for task load_to_mysql ('PythonOperator' object is not callable; 360302)
[2024-02-02T19:26:20.972+0000] {local_task_job_runner.py:234} INFO - Task exited with return code 1
[2024-02-02T19:26:21.012+0000] {taskinstance.py:3280} INFO - 0 downstream tasks scheduled from follow-on schedule check
