[2024-02-02T19:38:30.241+0000] {taskinstance.py:1956} INFO - Dependencies all met for dep_context=non-requeueable deps ti=<TaskInstance: etl_covid.load_to_mysql manual__2024-02-02T19:37:23.204801+00:00 [queued]>
[2024-02-02T19:38:30.250+0000] {taskinstance.py:1956} INFO - Dependencies all met for dep_context=requeueable deps ti=<TaskInstance: etl_covid.load_to_mysql manual__2024-02-02T19:37:23.204801+00:00 [queued]>
[2024-02-02T19:38:30.251+0000] {taskinstance.py:2170} INFO - Starting attempt 2 of 2
[2024-02-02T19:38:30.269+0000] {taskinstance.py:2191} INFO - Executing <Task(PythonOperator): load_to_mysql> on 2024-02-02 19:37:23.204801+00:00
[2024-02-02T19:38:30.275+0000] {standard_task_runner.py:60} INFO - Started process 366391 to run task
[2024-02-02T19:38:30.279+0000] {standard_task_runner.py:87} INFO - Running: ['airflow', 'tasks', 'run', 'etl_covid', 'load_to_mysql', 'manual__2024-02-02T19:37:23.204801+00:00', '--job-id', '32', '--raw', '--subdir', 'DAGS_FOLDER/scripts/Test.py', '--cfg-path', '/tmp/tmple97sfvk']
[2024-02-02T19:38:30.280+0000] {standard_task_runner.py:88} INFO - Job 32: Subtask load_to_mysql
[2024-02-02T19:38:30.336+0000] {task_command.py:423} INFO - Running <TaskInstance: etl_covid.load_to_mysql manual__2024-02-02T19:37:23.204801+00:00 [running]> on host bf5510de8451
[2024-02-02T19:38:30.428+0000] {taskinstance.py:2480} INFO - Exporting env vars: AIRFLOW_CTX_DAG_OWNER='airflow' AIRFLOW_CTX_DAG_ID='etl_covid' AIRFLOW_CTX_TASK_ID='load_to_mysql' AIRFLOW_CTX_EXECUTION_DATE='2024-02-02T19:37:23.204801+00:00' AIRFLOW_CTX_TRY_NUMBER='2' AIRFLOW_CTX_DAG_RUN_ID='manual__2024-02-02T19:37:23.204801+00:00'
[2024-02-02T19:38:30.490+0000] {taskinstance.py:2698} ERROR - Task failed with exception
Traceback (most recent call last):
  File "/home/airflow/.local/lib/python3.8/site-packages/mysql/connector/connection_cext.py", line 246, in _open_connection
    self._cmysql.connect(**cnx_kwargs)
_mysql_connector.MySQLInterfaceError: Can't connect to MySQL server on 'localhost:3306' (99)

During handling of the above exception, another exception occurred:

Traceback (most recent call last):
  File "/home/airflow/.local/lib/python3.8/site-packages/sqlalchemy/engine/base.py", line 3371, in _wrap_pool_connect
    return fn()
  File "/home/airflow/.local/lib/python3.8/site-packages/sqlalchemy/pool/base.py", line 327, in connect
    return _ConnectionFairy._checkout(self)
  File "/home/airflow/.local/lib/python3.8/site-packages/sqlalchemy/pool/base.py", line 894, in _checkout
    fairy = _ConnectionRecord.checkout(pool)
  File "/home/airflow/.local/lib/python3.8/site-packages/sqlalchemy/pool/base.py", line 493, in checkout
    rec = pool._do_get()
  File "/home/airflow/.local/lib/python3.8/site-packages/sqlalchemy/pool/impl.py", line 146, in _do_get
    self._dec_overflow()
  File "/home/airflow/.local/lib/python3.8/site-packages/sqlalchemy/util/langhelpers.py", line 70, in __exit__
    compat.raise_(
  File "/home/airflow/.local/lib/python3.8/site-packages/sqlalchemy/util/compat.py", line 211, in raise_
    raise exception
  File "/home/airflow/.local/lib/python3.8/site-packages/sqlalchemy/pool/impl.py", line 143, in _do_get
    return self._create_connection()
  File "/home/airflow/.local/lib/python3.8/site-packages/sqlalchemy/pool/base.py", line 273, in _create_connection
    return _ConnectionRecord(self)
  File "/home/airflow/.local/lib/python3.8/site-packages/sqlalchemy/pool/base.py", line 388, in __init__
    self.__connect()
  File "/home/airflow/.local/lib/python3.8/site-packages/sqlalchemy/pool/base.py", line 691, in __connect
    pool.logger.debug("Error on connect(): %s", e)
  File "/home/airflow/.local/lib/python3.8/site-packages/sqlalchemy/util/langhelpers.py", line 70, in __exit__
    compat.raise_(
  File "/home/airflow/.local/lib/python3.8/site-packages/sqlalchemy/util/compat.py", line 211, in raise_
    raise exception
  File "/home/airflow/.local/lib/python3.8/site-packages/sqlalchemy/pool/base.py", line 686, in __connect
    self.dbapi_connection = connection = pool._invoke_creator(self)
  File "/home/airflow/.local/lib/python3.8/site-packages/sqlalchemy/engine/create.py", line 574, in connect
    return dialect.connect(*cargs, **cparams)
  File "/home/airflow/.local/lib/python3.8/site-packages/sqlalchemy/engine/default.py", line 598, in connect
    return self.dbapi.connect(*cargs, **cparams)
  File "/home/airflow/.local/lib/python3.8/site-packages/mysql/connector/__init__.py", line 272, in connect
    return CMySQLConnection(*args, **kwargs)
  File "/home/airflow/.local/lib/python3.8/site-packages/mysql/connector/connection_cext.py", line 94, in __init__
    self.connect(**kwargs)
  File "/home/airflow/.local/lib/python3.8/site-packages/mysql/connector/abstracts.py", line 1052, in connect
    self._open_connection()
  File "/home/airflow/.local/lib/python3.8/site-packages/mysql/connector/connection_cext.py", line 251, in _open_connection
    raise errors.get_mysql_exception(msg=exc.msg, errno=exc.errno,
mysql.connector.errors.DatabaseError: 2003 (HY000): Can't connect to MySQL server on 'localhost:3306' (99)

The above exception was the direct cause of the following exception:

Traceback (most recent call last):
  File "/home/airflow/.local/lib/python3.8/site-packages/airflow/models/taskinstance.py", line 433, in _execute_task
    result = execute_callable(context=context, **execute_callable_kwargs)
  File "/home/airflow/.local/lib/python3.8/site-packages/airflow/operators/python.py", line 199, in execute
    return_value = self.execute_callable()
  File "/home/airflow/.local/lib/python3.8/site-packages/airflow/operators/python.py", line 216, in execute_callable
    return self.python_callable(*self.op_args, **self.op_kwargs)
  File "/opt/airflow/dags/scripts/Test.py", line 75, in func_load_to_mysql
    df.to_sql('staging_covid_table', con=engine, if_exists='replace', index=False)
  File "/home/airflow/.local/lib/python3.8/site-packages/pandas/core/generic.py", line 2878, in to_sql
    return sql.to_sql(
  File "/home/airflow/.local/lib/python3.8/site-packages/pandas/io/sql.py", line 768, in to_sql
    with pandasSQL_builder(con, schema=schema, need_transaction=True) as pandas_sql:
  File "/home/airflow/.local/lib/python3.8/site-packages/pandas/io/sql.py", line 832, in pandasSQL_builder
    return SQLDatabase(con, schema, need_transaction)
  File "/home/airflow/.local/lib/python3.8/site-packages/pandas/io/sql.py", line 1539, in __init__
    con = self.exit_stack.enter_context(con.connect())
  File "/home/airflow/.local/lib/python3.8/site-packages/sqlalchemy/engine/base.py", line 3325, in connect
    return self._connection_cls(self, close_with_result=close_with_result)
  File "/home/airflow/.local/lib/python3.8/site-packages/sqlalchemy/engine/base.py", line 96, in __init__
    else engine.raw_connection()
  File "/home/airflow/.local/lib/python3.8/site-packages/sqlalchemy/engine/base.py", line 3404, in raw_connection
    return self._wrap_pool_connect(self.pool.connect, _connection)
  File "/home/airflow/.local/lib/python3.8/site-packages/sqlalchemy/engine/base.py", line 3374, in _wrap_pool_connect
    Connection._handle_dbapi_exception_noconnection(
  File "/home/airflow/.local/lib/python3.8/site-packages/sqlalchemy/engine/base.py", line 2208, in _handle_dbapi_exception_noconnection
    util.raise_(
  File "/home/airflow/.local/lib/python3.8/site-packages/sqlalchemy/util/compat.py", line 211, in raise_
    raise exception
  File "/home/airflow/.local/lib/python3.8/site-packages/sqlalchemy/engine/base.py", line 3371, in _wrap_pool_connect
    return fn()
  File "/home/airflow/.local/lib/python3.8/site-packages/sqlalchemy/pool/base.py", line 327, in connect
    return _ConnectionFairy._checkout(self)
  File "/home/airflow/.local/lib/python3.8/site-packages/sqlalchemy/pool/base.py", line 894, in _checkout
    fairy = _ConnectionRecord.checkout(pool)
  File "/home/airflow/.local/lib/python3.8/site-packages/sqlalchemy/pool/base.py", line 493, in checkout
    rec = pool._do_get()
  File "/home/airflow/.local/lib/python3.8/site-packages/sqlalchemy/pool/impl.py", line 146, in _do_get
    self._dec_overflow()
  File "/home/airflow/.local/lib/python3.8/site-packages/sqlalchemy/util/langhelpers.py", line 70, in __exit__
    compat.raise_(
  File "/home/airflow/.local/lib/python3.8/site-packages/sqlalchemy/util/compat.py", line 211, in raise_
    raise exception
  File "/home/airflow/.local/lib/python3.8/site-packages/sqlalchemy/pool/impl.py", line 143, in _do_get
    return self._create_connection()
  File "/home/airflow/.local/lib/python3.8/site-packages/sqlalchemy/pool/base.py", line 273, in _create_connection
    return _ConnectionRecord(self)
  File "/home/airflow/.local/lib/python3.8/site-packages/sqlalchemy/pool/base.py", line 388, in __init__
    self.__connect()
  File "/home/airflow/.local/lib/python3.8/site-packages/sqlalchemy/pool/base.py", line 691, in __connect
    pool.logger.debug("Error on connect(): %s", e)
  File "/home/airflow/.local/lib/python3.8/site-packages/sqlalchemy/util/langhelpers.py", line 70, in __exit__
    compat.raise_(
  File "/home/airflow/.local/lib/python3.8/site-packages/sqlalchemy/util/compat.py", line 211, in raise_
    raise exception
  File "/home/airflow/.local/lib/python3.8/site-packages/sqlalchemy/pool/base.py", line 686, in __connect
    self.dbapi_connection = connection = pool._invoke_creator(self)
  File "/home/airflow/.local/lib/python3.8/site-packages/sqlalchemy/engine/create.py", line 574, in connect
    return dialect.connect(*cargs, **cparams)
  File "/home/airflow/.local/lib/python3.8/site-packages/sqlalchemy/engine/default.py", line 598, in connect
    return self.dbapi.connect(*cargs, **cparams)
  File "/home/airflow/.local/lib/python3.8/site-packages/mysql/connector/__init__.py", line 272, in connect
    return CMySQLConnection(*args, **kwargs)
  File "/home/airflow/.local/lib/python3.8/site-packages/mysql/connector/connection_cext.py", line 94, in __init__
    self.connect(**kwargs)
  File "/home/airflow/.local/lib/python3.8/site-packages/mysql/connector/abstracts.py", line 1052, in connect
    self._open_connection()
  File "/home/airflow/.local/lib/python3.8/site-packages/mysql/connector/connection_cext.py", line 251, in _open_connection
    raise errors.get_mysql_exception(msg=exc.msg, errno=exc.errno,
sqlalchemy.exc.DatabaseError: (mysql.connector.errors.DatabaseError) 2003 (HY000): Can't connect to MySQL server on 'localhost:3306' (99)
(Background on this error at: https://sqlalche.me/e/14/4xp6)
[2024-02-02T19:38:30.503+0000] {taskinstance.py:1138} INFO - Marking task as FAILED. dag_id=etl_covid, task_id=load_to_mysql, execution_date=20240202T193723, start_date=20240202T193830, end_date=20240202T193830
[2024-02-02T19:38:30.518+0000] {standard_task_runner.py:107} ERROR - Failed to execute job 32 for task load_to_mysql ((mysql.connector.errors.DatabaseError) 2003 (HY000): Can't connect to MySQL server on 'localhost:3306' (99)
(Background on this error at: https://sqlalche.me/e/14/4xp6); 366391)
[2024-02-02T19:38:30.531+0000] {local_task_job_runner.py:234} INFO - Task exited with return code 1
[2024-02-02T19:38:30.562+0000] {taskinstance.py:3280} INFO - 0 downstream tasks scheduled from follow-on schedule check
