[2024-02-02T19:33:35.580+0000] {taskinstance.py:1956} INFO - Dependencies all met for dep_context=non-requeueable deps ti=<TaskInstance: etl_covid.load_to_mysql manual__2024-02-02T19:30:27.895221+00:00 [queued]>
[2024-02-02T19:33:35.588+0000] {taskinstance.py:1956} INFO - Dependencies all met for dep_context=requeueable deps ti=<TaskInstance: etl_covid.load_to_mysql manual__2024-02-02T19:30:27.895221+00:00 [queued]>
[2024-02-02T19:33:35.588+0000] {taskinstance.py:2170} INFO - Starting attempt 2 of 2
[2024-02-02T19:33:35.605+0000] {taskinstance.py:2191} INFO - Executing <Task(PythonOperator): load_to_mysql> on 2024-02-02 19:30:27.895221+00:00
[2024-02-02T19:33:35.610+0000] {standard_task_runner.py:60} INFO - Started process 363927 to run task
[2024-02-02T19:33:35.614+0000] {standard_task_runner.py:87} INFO - Running: ['airflow', 'tasks', 'run', 'etl_covid', 'load_to_mysql', 'manual__2024-02-02T19:30:27.895221+00:00', '--job-id', '27', '--raw', '--subdir', 'DAGS_FOLDER/scripts/Test.py', '--cfg-path', '/tmp/tmp4dlfpob8']
[2024-02-02T19:33:35.615+0000] {standard_task_runner.py:88} INFO - Job 27: Subtask load_to_mysql
[2024-02-02T19:33:35.670+0000] {task_command.py:423} INFO - Running <TaskInstance: etl_covid.load_to_mysql manual__2024-02-02T19:30:27.895221+00:00 [running]> on host bf5510de8451
[2024-02-02T19:33:35.759+0000] {taskinstance.py:2480} INFO - Exporting env vars: AIRFLOW_CTX_DAG_OWNER='airflow' AIRFLOW_CTX_DAG_ID='etl_covid' AIRFLOW_CTX_TASK_ID='load_to_mysql' AIRFLOW_CTX_EXECUTION_DATE='2024-02-02T19:30:27.895221+00:00' AIRFLOW_CTX_TRY_NUMBER='2' AIRFLOW_CTX_DAG_RUN_ID='manual__2024-02-02T19:30:27.895221+00:00'
[2024-02-02T19:33:35.760+0000] {taskinstance.py:2698} ERROR - Task failed with exception
Traceback (most recent call last):
  File "/home/airflow/.local/lib/python3.8/site-packages/airflow/models/taskinstance.py", line 433, in _execute_task
    result = execute_callable(context=context, **execute_callable_kwargs)
  File "/home/airflow/.local/lib/python3.8/site-packages/airflow/operators/python.py", line 199, in execute
    return_value = self.execute_callable()
  File "/home/airflow/.local/lib/python3.8/site-packages/airflow/operators/python.py", line 216, in execute_callable
    return self.python_callable(*self.op_args, **self.op_kwargs)
  File "/opt/airflow/dags/scripts/Test.py", line 73, in func_load_to_mysql
    df = extract_data()
TypeError: 'PythonOperator' object is not callable
[2024-02-02T19:33:35.769+0000] {taskinstance.py:1138} INFO - Marking task as FAILED. dag_id=etl_covid, task_id=load_to_mysql, execution_date=20240202T193027, start_date=20240202T193335, end_date=20240202T193335
[2024-02-02T19:33:35.784+0000] {standard_task_runner.py:107} ERROR - Failed to execute job 27 for task load_to_mysql ('PythonOperator' object is not callable; 363927)
[2024-02-02T19:33:35.826+0000] {local_task_job_runner.py:234} INFO - Task exited with return code 1
[2024-02-02T19:33:35.857+0000] {taskinstance.py:3280} INFO - 0 downstream tasks scheduled from follow-on schedule check
